File: Vms/Experiment 2022-06-01_CuMnAs_11_CuLMM.vms
VAMAS Surface Chemical Analysis Standard Data Transfer Format 1988 May 4
Specs
PHOIBOS HSA3500 DLD 150 R7[HWType 30:101] DLD
ppxcf1
?
1
Created by SpecsLab Prodigy, Version 4.91.3-r105809
NORM
REGULAR
1
0
0
0
0
0
1
CuLMM
Transmission cyclic
2022
6
1
10
51
19
0
9
File = C:/Users/ppxcf1/Desktop/Data/XPS/01-Jun-2022/Experiment 2022-06-01_CuMnAs (1).sle
Group = Transmission cyclic
First of group = 1
Spectrum ID = 11
Analyzer lens = SmallArea:1.5kV
Analyzer slit = 4:7x20c\B:open
Scan mode = FixedAnalyzerTransmission
Kinetic energy start = 906.61
OrdinateRange = [-22.000000, 22.000000]
XPS
Al
1486.61
0
0
0
54.500000
180.000000
FAT
20
1
4.14
0
0
0
0
0
CuLMM

-1
kinetic energy
eV
906.61
0.1
2
counts
d
Transmission
d
pulse counting
0.1
25
0
0
0
0
0
402
10293.6
16967.3
1
1
11811.7
1
11791.7
1
11824.7
1
11750.3
1
11907.8
1
11831.1
1
11725.2
1
11466.9
1
11753.2
1
11977.9
1
11937.3
1
11627.2
1
11844.6
1
11881.8
1
11850.3
1
11900.8
1
11835.6
1
11660.2
1
11723.7
1
11814.7
1
11901.9
1
11765.4
1
11783.1
1
11766.7
1
11894
1
11829.4
1
11796.9
1
11772.1
1
11943.7
1
12103.4
1
11815
1
11862
1
11984.4
1
11887.8
1
11953.5
1
11960.6
1
11888.7
1
11939.7
1
12090.1
1
12020.3
1
12115.4
1
12165.5
1
12123.8
1
12217.3
1
12194.2
1
12051.2
1
12084
1
12424.1
1
12279.2
1
12356.4
1
12450.8
1
12311.9
1
12304.2
1
12333.6
1
12374.5
1
12429
1
12523.6
1
12345.1
1
12561.2
1
12549.8
1
12593.4
1
12575.2
1
12539.5
1
12634.9
1
12769.8
1
12879.7
1
12946.6
1
12727.3
1
12654.4
1
12853.6
1
12793.3
1
12718.4
1
12841.4
1
12865.1
1
12852.6
1
12905.3
1
12846.2
1
12848.3
1
12982.5
1
12998.7
1
13060.1
1
13221.2
1
13139.5
1
13252.5
1
13367.3
1
13206.2
1
13215.7
1
13298.3
1
13147.7
1
13243.8
1
13440.5
1
13299
1
13596.3
1
13420.5
1
13553.8
1
13671.3
1
13707.3
1
13779.3
1
13856.8
1
14025.6
1
14215
1
14306.2
1
14678.5
1
14913.9
1
15448.6
1
15689.1
1
15941
1
16368.7
1
16405.7
1
16967.3
1
16877.9
1
16859.7
1
16780.6
1
16770.4
1
16342
1
15886.7
1
15491.7
1
15019.2
1
14701.2
1
14281.7
1
14121.1
1
13926.6
1
13508
1
13154.6
1
13201.6
1
12999.4
1
12772.3
1
12590.9
1
12478.7
1
12325.9
1
12397.1
1
12221.3
1
12334.6
1
12493.9
1
12345.7
1
12307.3
1
12492.6
1
12482.4
1
12532.6
1
12399.2
1
12414.7
1
12249.1
1
12087.4
1
11730.5
1
11821.8
1
11724.7
1
11600.1
1
11383.6
1
11298.5
1
11220.5
1
11246.2
1
11069.4
1
11057.9
1
10841.4
1
10910.6
1
10890
1
10910.9
1
10733.4
1
10596.9
1
10622.2
1
10801.2
1
10857.1
1
10664.9
1
10658.6
1
10847.9
1
10707.9
1
10752.8
1
10794.1
1
10699.9
1
10624.7
1
10624.1
1
10600.7
1
10794.4
1
10794
1
10679.4
1
10654.1
1
10524.8
1
10576.1
1
10630.5
1
10533.6
1
10551.1
1
10525.3
1
10507.1
1
10631.1
1
10616.4
1
10483.7
1
10500.9
1
10477.4
1
10313.7
1
10473.9
1
10373.9
1
10473.4
1
10433.8
1
10530.4
1
10433.3
1
10566.1
1
10398.6
1
10293.6
1
10444.5
1
10520
1
10364.3
1
end of experiment