File: Vms/Experiment 2022-06-01_CuMnAs_12_Ga3pP2p3.vms
VAMAS Surface Chemical Analysis Standard Data Transfer Format 1988 May 4
Specs
PHOIBOS HSA3500 DLD 150 R7[HWType 30:101] DLD
ppxcf1
?
1
Created by SpecsLab Prodigy, Version 4.91.3-r105809
NORM
REGULAR
1
0
0
0
0
0
1
Ga3pP2p3
Transmission cyclic
2022
6
1
10
52
6
0
9
File = C:/Users/ppxcf1/Desktop/Data/XPS/01-Jun-2022/Experiment 2022-06-01_CuMnAs (1).sle
Group = Transmission cyclic
First of group = 1
Spectrum ID = 12
Analyzer lens = SmallArea:1.5kV
Analyzer slit = 4:7x20c\B:open
Scan mode = FixedAnalyzerTransmission
Kinetic energy start = 1351.61
OrdinateRange = [-22.000000, 22.000000]
XPS
Al
1486.61
0
0
0
54.500000
180.000000
FAT
20
1
4.14
0
0
0
0
0
Ga3pP2p3

-1
kinetic energy
eV
1351.61
0.1
2
counts
d
Transmission
d
pulse counting
0.1
16
0
0
0
0
0
702
961.389
2690.31
1
1
1329.51
1
1299.64
1
1280.56
1
1269.41
1
1190.95
1
1232.1
1
1255.38
1
1256.74
1
1305.22
1
1350.71
1
1254.85
1
1270.86
1
1300.3
1
1243.32
1
1226.83
1
1213.17
1
1259.84
1
1275.25
1
1257.15
1
1277.91
1
1306.12
1
1251.07
1
1190.44
1
1228.04
1
1236.02
1
1224.58
1
1274.86
1
1150.85
1
1217.87
1
1221.29
1
1252.31
1
1198.46
1
1209.23
1
1169.11
1
1234.06
1
1245.23
1
1192.4
1
1233.96
1
1308.33
1
1285.08
1
1311.68
1
1311.12
1
1393.78
1
1407.44
1
1471.01
1
1585.45
1
1703.95
1
1855.03
1
1973.23
1
1998.6
1
2052.6
1
2089.51
1
1992.52
1
2034.25
1
2120.63
1
2365.4
1
2614.21
1
2681.57
1
2690.31
1
2393.55
1
2230
1
2005.01
1
1769.07
1
1548.45
1
1450.06
1
1362.78
1
1309.22
1
1307.19
1
1303.78
1
1261.44
1
1311.03
1
1324.2
1
1315.04
1
1301.45
1
1256.96
1
1321.89
1
1317.61
1
1379.45
1
1390.96
1
1279.68
1
1305.08
1
1278.76
1
1306.92
1
1312.67
1
1331.8
1
1344.73
1
1420.53
1
1412.75
1
1392.79
1
1390.09
1
1459.88
1
1449.74
1
1413.4
1
1449.03
1
1412.13
1
1498.87
1
1480.83
1
1481.92
1
1580.29
1
1561.99
1
1527.52
1
1641.44
1
1635.97
1
1569.9
1
1624.8
1
1675.22
1
1774.92
1
1802.29
1
1763.13
1
1819.51
1
1829.56
1
1985.37
1
1908.14
1
1895.01
1
1892.75
1
1902.34
1
1934.7
1
1911.98
1
1884.92
1
1850.21
1
1783.15
1
1789.37
1
1794.39
1
1743.53
1
1713.92
1
1703.64
1
1644.47
1
1547.86
1
1606.83
1
1584.68
1
1577.45
1
1533.17
1
1466.04
1
1495.7
1
1441.84
1
1451.51
1
1446.11
1
1460.45
1
1524.54
1
1418.75
1
1307.23
1
1343.58
1
1365.8
1
1325.35
1
1307.06
1
1356.3
1
1266.61
1
1237.68
1
1269.58
1
1261.09
1
1236.7
1
1272.81
1
1246.68
1
1214.76
1
1256.42
1
1247.42
1
1203.34
1
1182.33
1
1243.12
1
1186.54
1
1168.09
1
1183.43
1
1173.79
1
1216.16
1
1175.4
1
1186.44
1
1104.76
1
1172.49
1
1153.05
1
1149.88
1
1160.67
1
1171.31
1
1132.54
1
1100.89
1
1134.29
1
1090.13
1
1155.38
1
1120.63
1
1143.23
1
1063.98
1
1072.64
1
1092.27
1
1123.66
1
1090.1
1
1044.12
1
1086.81
1
1042.5
1
1033.13
1
1093.36
1
1115.33
1
1063.1
1
1093.35
1
1073.5
1
1100.98
1
1058.44
1
1073.61
1
1100.93
1
1038.42
1
1100.18
1
1061.57
1
1071.2
1
1057.48
1
1103.9
1
1041.87
1
1018.98
1
1032.87
1
1097.49
1
1062.7
1
1042.45
1
1043.04
1
1067.22
1
1057.41
1
1106.95
1
1065.73
1
1075.14
1
1038.96
1
1068.01
1
1078.17
1
1023.2
1
1025.23
1
1061.02
1
1068.24
1
1027.42
1
1028.09
1
1091.67
1
1045.09
1
1088.28
1
1102.31
1
1077.85
1
1116.95
1
1092.84
1
1056.22
1
1052.7
1
1069.71
1
1092.77
1
1145.69
1
1090.58
1
1098.83
1
1089.14
1
1094.27
1
1101.16
1
1144.9
1
1123.09
1
1146.94
1
1172.57
1
1222.8
1
1222.79
1
1188.76
1
1211.21
1
1271.28
1
1284.63
1
1328.66
1
1384.21
1
1424.51
1
1405.47
1
1420.64
1
1483.87
1
1529.49
1
1480.08
1
1524.59
1
1523.49
1
1637.45
1
1623
1
1554.7
1
1639.14
1
1610.96
1
1615.29
1
1598.84
1
1656.88
1
1582.45
1
1520.71
1
1535.05
1
1426.03
1
1454.59
1
1455.81
1
1373.04
1
1370.21
1
1422.21
1
1443.59
1
1406.27
1
1408.27
1
1407.26
1
1471.62
1
1502.29
1
1569.21
1
1572.06
1
1659.05
1
1653.37
1
1634.02
1
1655.91
1
1732.1
1
1781.92
1
1841.42
1
1893.53
1
1895.97
1
1922.55
1
2063.4
1
2081.03
1
2051.28
1
2078.32
1
1978.91
1
1999.3
1
2081.74
1
2026.53
1
1942.62
1
1806.36
1
1813.04
1
1714.61
1
1607.91
1
1578.13
1
1590.01
1
1531.1
1
1457.09
1
1418.8
1
1416.46
1
1355.48
1
1376.67
1
1295.29
1
1240.11
1
1197.36
1
1167.67
1
1268.66
1
1214.22
1
1176.59
1
1147.29
1
1126.35
1
1090.21
1
1187.99
1
1093.49
1
1088.29
1
1065.26
1
1103.65
1
1072.19
1
1093.07
1
1057.92
1
1062.06
1
1058.36
1
1049.24
1
1026.27
1
1038.32
1
1054.88
1
1065.73
1
1017.61
1
1011.83
1
1023.57
1
999.533
1
984.568
1
961.389
1
998.85
1
1055.58
1
1053.88
1
end of experiment