File: Vms/Experiment 2022-06-01_CuMnAs_3_Wide1.vms
VAMAS Surface Chemical Analysis Standard Data Transfer Format 1988 May 4
Specs
PHOIBOS HSA3500 DLD 150 R7[HWType 30:101] DLD
ppxcf1
?
1
Created by SpecsLab Prodigy, Version 4.91.3-r105809
NORM
REGULAR
1
0
0
0
0
0
1
Wide1
Transmission cyclic
2022
6
1
8
40
8
0
9
File = C:/Users/ppxcf1/Desktop/Data/XPS/01-Jun-2022/Experiment 2022-06-01_CuMnAs (1).sle
Group = Transmission cyclic
First of group = 1
Spectrum ID = 3
Analyzer lens = SmallArea:1.5kV
Analyzer slit = 4:7x20c\B:open
Scan mode = FixedAnalyzerTransmission
Kinetic energy start = 386.61
OrdinateRange = [-22.000000, 22.000000]
XPS
Al
1486.61
0
0
0
54.500000
180.000000
FAT
100
1
4.14
0
0
0
0
0
Wide1

-1
kinetic energy
eV
386.61
1
2
counts
d
Transmission
d
pulse counting
0.1
0
0
0
0
1
3415.52
3351.79
3436.78
3419.19
3442.84
3451.22
3524.3
3511.45
3492.03
3520.88
3592.59
3571.36
3563.82
3598.79
3520.56
3542.98
3433.47
3484.06
3536.67
3615.93
3522.29
3682.43
3667.92
3749.47
3723.75
3598.17
3589.34
3728.81
3690.22
3784.13
3733.44
3733.69
3652.76
3720.34
3821.08
3749.83
3900.35
3681.24
3755.69
3744.68
3741.33
3845.49
3866.61
3742.13
3769.22
3854.63
3842.22
3781.95
3857.58
3892.11
3901.33
3892.19
3942.36
3902.77
3923.78
3831.1
3934.74
3808.99
3935.94
3987.16
4088.07
3998.05
4031.81
4040.74
4072.2
4037.47
4000.91
4039.3
4062.1
4111.44
4184.59
4034.13
4068.43
4136.33
4170.22
4172.96
4173.01
4109.39
4160.94
4173.41
4139.37
4208.36
4228.45
4215.16
4299.47
4280.55
4309.52
4167.7
4227.65
4369.01
4340.32
4380.49
4422.66
4363.57
4362.59
4390.09
4329.79
4410.94
4549.55
4399.61
4369.31
4567.4
4575.45
4507.44
4493.8
4565.82
4558.76
4621.28
4505.36
4421.7
4583.64
4537.69
4509.86
4650.13
4655.59
4632.15
4536.95
4687.11
4749.65
4688.39
4772.34
4723.26
4712.16
4800.39
4816.63
4821.98
4870.08
4778.69
4675.3
4606.96
4720.45
4684.16
4713.87
4718.92
4635.18
4581.7
4694.8
4545.72
4715.84
4628.11
4809.76
4851.21
4706.59
4646.15
4682.58
4800.33
4886.34
4726.91
4747.26
4740.89
4805.33
4888.7
4894.07
4856.88
4864.92
4902.3
4797.85
4880.27
4888.86
4909.3
4975.79
4962.28
5002.88
5080.12
5028.87
4948.31
5066.17
5045.81
5126.84
5027
5080.17
5046.21
5011.39
4974.42
4992.38
5049.88
5029.41
4997.7
5111.44
5052.57
5090.83
5047.5
5085.62
5156.7
5090.73
5102.94
5106.83
5104.82
5205.4
5188.02
5088.43
5280.8
5217.14
5201.42
5079.83
5140.19
5263.47
5270.03
5310.72
5277.1
5366.3
5330.05
5210.57
5341.29
5394.94
5358.96
5289.19
5385.42
5477.88
5568.15
5469.64
5372.05
5378.97
5514.36
5367.06
5395.2
5385.98
5542.82
5467.34
5493.31
5553.29
5496.1
5581.89
5573.07
5609.8
5548.21
5575.75
5553.07
5689.44
5718.66
5743.58
5660.11
5642.3
5691.05
5768.81
5655.86
5722.72
5671.32
5795.97
5722.38
5763.24
5790.63
5707.95
5739.68
5598.55
5798.46
5862.32
5888.43
5846.12
5891.58
5877.16
5784.32
5916.78
5841.92
5832.2
5926.65
6003.69
5874.13
5929.27
5875.7
5963.76
5887.11
5938.92
5932.3
5947.82
5993.58
5989.48
5933.07
6090.74
6086.34
5982.53
5950.17
6113.59
6164.98
6116.2
6182.11
5991.14
6110.08
6118.62
6147.39
5983.74
6119.02
6053.37
6247.65
6285.16
6192.18
6341.87
6242.18
6329.6
6227.72
6281.42
6232.28
6265.65
6273.81
6285.97
6364.36
6444.66
6484.83
6441.57
6287.52
6277.73
6371.03
6541.09
6432.04
6471.27
6475.63
6399.81
6477.93
6487.09
6432.83
6505.29
6574.27
6568.86
6690.03
6680.64
6591.43
6573.4
6680.27
6547.71
6564.24
6594.45
6648.51
6672.66
6765.12
6661.59
6732.26
6741.54
6809.4
6639.67
6672.55
6774.15
6826.28
6903.99
6851.23
6897.13
6876.36
6796.87
7000.44
6906.84
6828.59
6887.77
6940.91
6979.07
6869.2
6843.38
6927.22
6989.9
6866.9
6913.53
7021.3
6978.2
6894.21
7028.59
7029.26
7108.02
6990.31
7062.55
7011.9
7069.01
7131.52
7069.61
7130.96
7102.91
7228.28
7367.49
7351.17
7152.34
7195.77
7319.71
7303.06
7228.26
7297.62
7343.52
7288.88
7424.68
7369.32
7345.53
7227.52
7286.61
7472.45
7466.72
7503.56
7553.85
7353.92
7405.42
7599.87
7617.88
7422.67
7448.63
7282.62
7481.43
7499.64
7482.26
7576.93
7562.85
7604.65
7608.92
7468.48
7683.02
7640.36
7755.58
7700.11
7787.86
7837.62
7960.96
7785.21
7669.06
7717.56
7687.76
7852.38
7686.69
7728.56
7873
7724.91
7799.51
7866.23
7850.75
7784.93
7983.19
7967.9
8013.84
8151.16
7941.31
7988.88
7996.66
7867.42
7992.9
8002.27
8088.11
7953.86
7975.12
7961.43
7937.31
8013.43
7960.74
8159.18
8039.12
7987.56
7965.28
8113.71
8146.1
8311.18
8381.49
8193.6
8243.61
8350.19
8316.14
8166.1
8335.5
8295.66
8211.51
8217.04
8142.41
8231.32
8204.86
8307.22
8210.48
8337.38
8317.2
8480.55
8400.62
8415.2
8394.67
8561.58
8587.75
8274.71
8463.51
8502.83
8449.78
8478.97
8613.94
8555.21
8591.55
8679.06
8717.91
8663.63
8722.89
8716.77
8577.78
8629.73
8702.13
8768.8
8758
8770.86
8865.94
8969.02
8878.22
8824.03
8745.73
8821.14
8918.48
8777.06
8943.61
8948.5
8837.38
8888.36
8982.06
9012.92
8997.85
9098.02
9018.64
8918.84
9075.89
9105.21
9261.77
9250.73
9138.44
9206.52
9246.02
9337.96
9460.29
9396.67
9436.16
9383.89
9381.72
9310.58
9403.96
9438.41
9329.45
9235.39
9319.8
9564.12
9663.81
9445.21
9674.8
9579.09
9569.86
9610.28
9723.24
9731.7
9707.69
9730.26
9862.8
9757.33
9810.38
9799.22
9895.04
10026.7
9843.43
9896.21
10006.3
9880.82
10023.5
10171.9
10041.8
9976.22
10199.6
10135.9
10197.5
10298
10130.5
10094.4
9991.83
10122.6
10104.4
10095.2
10108.9
10269.1
10404.2
10456.8
10406.7
10511.6
10601
10730.4
10735.5
10853.3
10694.1
10856.8
10957.7
10915.3
10665.4
10578
10598.9
10352.4
10342.1
10365.3
10731.3
10764.6
10651.5
10649
10925
10773.5
10863.1
10812.3
10757.3
10813.3
10726.6
10839.6
10658.8
10620.3
10778.1
10836.2
10800.5
10919.4
10902.4
11092.9
11150.6
11115.2
10959.5
10991.5
11064.4
11032.2
11167.8
11238
11029.6
10884.1
10972.9
11102.7
11297.1
11336.1
11250.4
11129.4
11196.2
11299.9
11331.8
11404.1
11328.2
11488.8
11454.3
11654.6
11535.9
11495.3
11525.7
11664.9
11564.4
11527
11408
11688.7
11634.5
11551.7
11693.6
11660.4
11707.3
11776.9
11577
11531.1
11415.4
11324.6
11321.5
11599.6
11567.3
11616
11461.9
11295.9
11053.1
10788.1
10760.4
10549.4
10493.2
10463.4
10506
10386.7
10279.7
10493.1
10588.6
10654.4
10606.1
10625.8
10644.3
10571.2
10580.7
10577.4
10539.9
10658.1
10661.3
10766.7
10682
10924.1
11041.3
10873.8
11027.2
10806.4
10405.5
10669.8
10481.8
10690.7
10647.8
10340.2
10336.8
10368.5
10312.3
10073.2
10323.4
10279.2
10297.3
10155
10456
10559.7
10431.4
10467.1
10375.9
10541.6
10708.5
10825.3
10718.3
10581
10767.5
10757.5
10692.1
10630.9
10690.6
10866.8
10895.4
11056.4
11101.2
10971.4
11016
11329.2
11232.3
11526.3
11486.1
11315.2
11272.8
11290.2
11279
11154.3
11216.9
11098.2
11189.2
11298.7
11300.6
11358.5
11465.4
11475.7
11587.4
11935.1
12105.5
12213.4
12466
12412.6
12044
11342.2
11051.7
10377.4
10199.9
10274.2
10478.1
10798.3
11072
11335.9
11245.3
10865.4
10397.7
10126.3
9864.14
9683.05
9491.15
9321.65
9245.98
9141.08
8986.45
8767.49
8944.87
8924.8
8737.32
8839.68
8972.84
9067.22
8978.14
9087.73
9252.57
9372.26
9590.07
9968.81
9960.14
10050.1
9785.27
9173.72
8958.97
8895.97
8886.99
8996.9
8911.87
8972.91
8948.29
8876.17
8850.19
8690.24
8538.72
8521.15
8488.14
8580.96
8584.01
8592.71
8666.44
8563.14
8593.79
8748.45
8767.08
8764.87
8891.2
8947.44
8954.2
8794.67
8805.86
8909.21
8931.65
8883.39
9139.23
9154.12
9237.55
9229.13
9146.91
9411.21
9174.16
9162.78
9155.13
8975.35
8963.66
9282.49
9444.17
9513.04
9576.53
9870.63
10208.5
10389.5
10320.4
10151.7
10487.7
10542.8
10636.9
10487.7
10406.1
10045.3
9583.85
9404.71
9174.79
8945.61
8859.55
8583.4
8787.35
8900.9
9099.97
9077.09
9644.88
10176.2
11432.6
13586
15601.1
14470.7
11853.2
10070.1
9415.18
8592.15
7424.37
6094.77
5480.71
5143.36
5027.33
4942.48
5131.93
5059.32
5192.93
5217.92
5497.45
5569.02
5574.96
5385.59
5227.88
5057.03
4870.49
4778.98
4885.45
4667.66
4539.56
4546.17
4566.04
4649.67
4815.84
4924.94
5142.71
5332.67
6197.79
7596.03
8234.41
7259.83
5914.58
4852.09
4300.38
3826.81
3313.36
2862.72
2885.97
2665.47
2602.28
2643.32
2626.22
2757.84
2865.44
2861.43
2757.13
2893.3
3104.78
3278.88
3502
3382.37
3045.68
2569.37
2323.51
2377.37
2288.33
2285.93
2218.09
2224.04
2206.59
2208.88
2183.4
2133.2
2203.84
2204.54
2246.28
2317.43
2311
2327.09
2276.26
2333.72
2259.69
2278.5
2370.34
2374.78
2381.1
2423
2359.01
2365.47
2460.49
2440.34
2367.36
2310.56
2252.52
2372.2
2389.12
2466.91
2478
2460.27
2529.7
2602.36
2731.61
2661
2701.89
2651.49
2527.5
2500.95
2371.73
2249.96
2180.36
2054.92
2052.78
1969.13
1991.13
2066.37
2172.89
2358.11
2600.32
3061.04
3238.05
3041.11
2833.17
3099.88
3655.4
3469.49
2680.33
1703.02
1204.53
973.101
845.371
820.61
753.454
745.603
725.926
713.782
694.86
688.277
671.256
681.493
699.729
627.432
715.294
775.417
722.82
732.397
732.822
668.165
689.531
698.63
707.57
734.693
723.696
682.708
704.812
679.726
712.179
725.445
700.776
713.276
742.991
720.669
734.409
809.101
752.3
786.455
759.27
723.035
769.573
796.419
800.079
778.035
796.093
829.878
829.878
772.326
755.119
808.283
802.728
817.298
836.207
841.312
794.064
883.253
808.316
847.86
860.247
907.848
904.293
865.661
830.323
828.868
828.68
811.321
827.732
844.566
832.841
894.041
873.852
895.007
941.462
962.089
992.359
1092.26
1220.84
1186.48
1156.13
1044.74
946.506
830.319
754.622
659.49
660.618
691.608
667.726
684.116
692.239
717.272
774.715
794.397
899.4
1097.59
1648.78
2930.12
2989.74
1583.46
539.043
231.867
183.522
164.037
134.26
125.596
126.255
131.361
132.077
137.533
155.594
150.566
143.484
157.931
155.034
154.863
139.77
158.789
150.893
123.785
115.678
117.083
119.343
137.872
133.065
149.019
127.142
152.956
151.396
153.331
144.868
131.086
101.918
104.191
138.416
152.842
173.778
175.328
134.287
61.43
20.2715
4.97921
2.33141
1.44408
1.27959
0
1
end of experiment