File: Vms/Experiment 2022-06-01_CuMnAs_17_CuLMM4.vms
VAMAS Surface Chemical Analysis Standard Data Transfer Format 1988 May 4
Specs
PHOIBOS HSA3500 DLD 150 R7[HWType 30:101] DLD
ppxcf1
?
1
Created by SpecsLab Prodigy, Version 4.91.3-r105809
NORM
REGULAR
1
0
0
0
0
0
1
CuLMM4
Transmission cyclic
2022
6
1
13
24
2
0
9
File = C:/Users/ppxcf1/Desktop/Data/XPS/01-Jun-2022/Experiment 2022-06-01_CuMnAs (1).sle
Group = Transmission cyclic
First of group = 1
Spectrum ID = 17
Analyzer lens = SmallArea:1.5kV
Analyzer slit = 4:7x20c\B:open
Scan mode = FixedAnalyzerTransmission
Kinetic energy start = 906.61
OrdinateRange = [-22.000000, 22.000000]
XPS
Al
1486.61
0
0
0
54.500000
180.000000
FAT
20
1
4.14
0
0
0
0
0
CuLMM4

-1
kinetic energy
eV
906.61
0.1
2
counts
d
Transmission
d
pulse counting
0.5
50
0
0
0
0
0
402
25803.9
42370.1
1
1
29267
1
29469.1
1
29245
1
29517.7
1
29418.2
1
29806.9
1
29766.8
1
29696.3
1
29617.8
1
29652.4
1
29714.1
1
29548.7
1
29740.6
1
29655.7
1
29758.4
1
29582.6
1
29432.8
1
29576.3
1
29738.1
1
29692.6
1
29884.4
1
29845.5
1
29786.4
1
29690.9
1
29620.2
1
29823.3
1
29736.9
1
29690.7
1
29668.4
1
29580.2
1
29552.2
1
29951.6
1
29891.6
1
30003.9
1
30089.9
1
29816.5
1
29734.6
1
30148.6
1
30052.3
1
29899.4
1
29760.3
1
29863.8
1
30133.7
1
30056.8
1
30415
1
30301.8
1
30460.4
1
30531.8
1
30520.3
1
30750.8
1
30669.1
1
30893.6
1
30999.3
1
31109.6
1
31196.2
1
31282.7
1
31554.7
1
31202.4
1
31054.4
1
31425.3
1
31617.7
1
31567.9
1
31702.9
1
31963.5
1
31777.2
1
31689.9
1
31671.7
1
31694.5
1
31518.7
1
31462.4
1
31357.6
1
31908.8
1
31620.8
1
31678
1
31955.5
1
31821.7
1
31786.1
1
31856
1
32252.4
1
32263.2
1
32596.3
1
32685.3
1
32592.6
1
32849.9
1
32746
1
32930.5
1
32997.3
1
33260.6
1
32959.6
1
32912.8
1
33076.5
1
33409.4
1
33423.6
1
33562
1
33645.1
1
33599.2
1
33916.7
1
34249.6
1
34699.3
1
35084.3
1
35602.6
1
36113.6
1
36789.1
1
37402.3
1
38131.3
1
38747.7
1
39546.8
1
40789.2
1
41767.1
1
42131
1
42370.1
1
42246.8
1
41670.6
1
41350.9
1
40349.1
1
39355
1
38402.7
1
37275.6
1
36144
1
35420.8
1
34795.2
1
34019.7
1
33485.4
1
33091.6
1
32483.5
1
31835.4
1
31741.7
1
31463.4
1
31133.2
1
30949
1
30204.9
1
30495.4
1
30696.2
1
30777.6
1
31025.7
1
31024
1
31159
1
31283.8
1
31278
1
31242.9
1
31238.5
1
30504.3
1
29973.2
1
30001.4
1
29085.8
1
28823.3
1
28735.5
1
28562.4
1
27988.3
1
27737.6
1
27231.1
1
27115.7
1
27097.1
1
26870
1
26942.7
1
26816.5
1
26857.2
1
26640.8
1
26605.1
1
26557.4
1
26524.4
1
26409.6
1
26375.9
1
26779.4
1
26744.9
1
26723.3
1
26493.8
1
26527.1
1
26520.8
1
26453.9
1
26207.4
1
26496.5
1
26276.5
1
26323.4
1
26466
1
26449.4
1
26201.1
1
25835.8
1
26314
1
26473.9
1
26088
1
26205.9
1
26193.9
1
26284.3
1
26050.2
1
25955.2
1
25952.4
1
26000
1
25982.8
1
26236.7
1
26307.8
1
26266.6
1
26122.7
1
25915.8
1
26018.7
1
26257
1
26147.1
1
26093
1
25803.9
1
26023.1
1
25929.9
1
end of experiment