File: Vms/Experiment 2022-06-01_CuMnAs_18_Ga3pP2p4.vms
VAMAS Surface Chemical Analysis Standard Data Transfer Format 1988 May 4
Specs
PHOIBOS HSA3500 DLD 150 R7[HWType 30:101] DLD
ppxcf1
?
1
Created by SpecsLab Prodigy, Version 4.91.3-r105809
NORM
REGULAR
1
0
0
0
0
0
1
Ga3pP2p4
Transmission cyclic
2022
6
1
13
27
18
0
9
File = C:/Users/ppxcf1/Desktop/Data/XPS/01-Jun-2022/Experiment 2022-06-01_CuMnAs (1).sle
Group = Transmission cyclic
First of group = 1
Spectrum ID = 18
Analyzer lens = SmallArea:1.5kV
Analyzer slit = 4:7x20c\B:open
Scan mode = FixedAnalyzerTransmission
Kinetic energy start = 1351.61
OrdinateRange = [-22.000000, 22.000000]
XPS
Al
1486.61
0
0
0
54.500000
180.000000
FAT
20
1
4.14
0
0
0
0
0
Ga3pP2p4

-1
kinetic energy
eV
1351.61
0.1
2
counts
d
Transmission
d
pulse counting
0.5
50
0
0
0
0
0
702
4263.46
7497.28
1
1
5271.59
1
5174.7
1
5239.62
1
4970.28
1
5064.66
1
5097.68
1
5121.68
1
5028.89
1
5185.81
1
5234.37
1
5083.71
1
5086.65
1
4972.22
1
4973.45
1
4946.21
1
4972.15
1
5080.26
1
5078.07
1
4937.49
1
4928.33
1
4985.81
1
4871.48
1
4983.53
1
4982.9
1
4956.86
1
4840.52
1
4913.25
1
4958.73
1
4905.59
1
4973.77
1
4915.56
1
4903.63
1
4955.76
1
4941.18
1
4822.01
1
4898.37
1
4947.45
1
4957.81
1
5184.8
1
5119.5
1
5147.38
1
5226.24
1
5278.11
1
5556.07
1
5838.21
1
6093.42
1
6096.58
1
6401.95
1
6391.31
1
6279.88
1
6298.44
1
6349.38
1
6619.51
1
6951.27
1
7091.31
1
7470.91
1
7497.28
1
7065.32
1
6803.2
1
6302.49
1
5911.79
1
5528.4
1
5373.28
1
5186.42
1
5167.04
1
5089.92
1
5025.53
1
5105.72
1
5130.38
1
5080.06
1
5041.77
1
4986.86
1
5115.09
1
5066.71
1
5114.36
1
5218.17
1
5153.98
1
5138.42
1
5060.8
1
5039.75
1
5094.87
1
5097.77
1
5253.11
1
5326.98
1
5308.62
1
5372.85
1
5379.94
1
5322.73
1
5378.86
1
5421.33
1
5330.69
1
5349.05
1
5431.67
1
5520.65
1
5612.51
1
5740.51
1
5661.71
1
5806.7
1
5879.38
1
5967.08
1
5964.87
1
6025.7
1
6195.18
1
6248.37
1
6481.01
1
6477.61
1
6562.66
1
6662.56
1
6854.84
1
6745.03
1
6971.51
1
7118.53
1
7265.13
1
7239.62
1
7322.55
1
7322.98
1
7288.75
1
7362.13
1
7209.3
1
7196.72
1
6990.12
1
6905.04
1
6730.62
1
6697.07
1
6600.87
1
6295.8
1
6260.61
1
6256.78
1
6164.09
1
6017.75
1
5857.49
1
5708.97
1
5531.63
1
5542.15
1
5480.95
1
5557.57
1
5386.35
1
5477.96
1
5411.52
1
5252.28
1
5196.91
1
5217.15
1
5140.85
1
5193.95
1
5095.83
1
5079.41
1
5090.84
1
5075.82
1
4966.76
1
4873.42
1
4863.38
1
4905.55
1
4965.66
1
4828.74
1
4828.01
1
4810.67
1
4926.24
1
4810.54
1
4736.59
1
4753.3
1
4743.98
1
4596.53
1
4716.6
1
4683.65
1
4624.07
1
4540.94
1
4626.52
1
4511.32
1
4656.12
1
4543.04
1
4575.67
1
4559.38
1
4518.92
1
4612.9
1
4600.47
1
4577
1
4533.98
1
4648.27
1
4649.66
1
4598.88
1
4733.11
1
4681.03
1
4503.99
1
4491.04
1
4495.7
1
4571.25
1
4596.19
1
4557.12
1
4484.29
1
4539.64
1
4410.22
1
4444.41
1
4449.36
1
4538.37
1
4458.73
1
4405.23
1
4366.97
1
4299.19
1
4423.89
1
4365.01
1
4420.11
1
4386.44
1
4397.15
1
4405.22
1
4356.21
1
4334.39
1
4313.1
1
4407.98
1
4472.32
1
4392.38
1
4360.85
1
4267.83
1
4328.68
1
4386.39
1
4338.16
1
4427.89
1
4444.03
1
4419.99
1
4388.73
1
4388.88
1
4318.34
1
4309.43
1
4268.42
1
4343.87
1
4361.8
1
4380.1
1
4263.46
1
4338.47
1
4356.19
1
4314.85
1
4276.7
1
4351.3
1
4401.64
1
4411.86
1
4401.86
1
4382.56
1
4365.61
1
4346.91
1
4420.21
1
4396.65
1
4297.19
1
4303.6
1
4558.87
1
4616.09
1
4616.37
1
4686.44
1
4609.04
1
4644.76
1
4718.81
1
4848.74
1
4859.59
1
4905.16
1
5065.62
1
5059.11
1
5034.27
1
5073.64
1
5210.07
1
5268.49
1
5310.73
1
5410.48
1
5431.79
1
5511.99
1
5489.94
1
5564.84
1
5508.88
1
5426.74
1
5386.32
1
5332.16
1
5210.81
1
5262.53
1
5167.74
1
5174.93
1
5175.32
1
5096.54
1
5107.3
1
5158.68
1
5042.67
1
4990.42
1
5067.26
1
5180.24
1
5142.14
1
5143.98
1
5231.46
1
5198.37
1
5284.89
1
5399
1
5378.47
1
5477.1
1
5663.99
1
5820.09
1
5848.35
1
6112.12
1
6153.37
1
6261.18
1
6213.65
1
6341.92
1
6393.95
1
6489.18
1
6377.57
1
6475.3
1
6333.77
1
6323.16
1
6201.07
1
5957.56
1
5770.04
1
5785.9
1
5653.72
1
5557.1
1
5476.25
1
5343.53
1
5342.17
1
5093.2
1
5066.58
1
5080.83
1
4926
1
4885.4
1
4897.99
1
4829.66
1
4685.89
1
4698.61
1
4691.65
1
4654.96
1
4609.99
1
4543.11
1
4596.36
1
4632.23
1
4435.93
1
4572.27
1
4523.97
1
4492.65
1
4472.19
1
4463.46
1
4454.55
1
4389.64
1
4428.68
1
4427.06
1
4426.2
1
4381.72
1
4452.63
1
4285.53
1
4354.44
1
4417.68
1
4401.33
1
4405.09
1
4398.46
1
4432.08
1
4474.76
1
4380.21
1
4292.81
1
4382.04
1
4365.66
1
end of experiment