File: Vms/Experiment 2022-06-01_CuMnAs_13_Wide4.vms
VAMAS Surface Chemical Analysis Standard Data Transfer Format 1988 May 4
Specs
PHOIBOS HSA3500 DLD 150 R7[HWType 30:101] DLD
ppxcf1
?
1
Created by SpecsLab Prodigy, Version 4.91.3-r105809
NORM
REGULAR
1
0
0
0
0
0
1
Wide4
Transmission cyclic
2022
6
1
11
8
53
0
9
File = C:/Users/ppxcf1/Desktop/Data/XPS/01-Jun-2022/Experiment 2022-06-01_CuMnAs (1).sle
Group = Transmission cyclic
First of group = 1
Spectrum ID = 13
Analyzer lens = SmallArea:1.5kV
Analyzer slit = 4:7x20c\B:open
Scan mode = FixedAnalyzerTransmission
Kinetic energy start = 386.61
OrdinateRange = [-22.000000, 22.000000]
XPS
Al
1486.61
0
0
0
54.500000
180.000000
FAT
100
1
4.14
0
0
0
0
0
Wide4

-1
kinetic energy
eV
386.61
1
2
counts
d
Transmission
d
pulse counting
0.5
0
0
0
3.16834
1
6901.59
6965.65
7106.8
7076.7
7046.06
6736.51
6848.94
6872.5
6861.54
6715.86
6668.24
6705.68
6769.11
6933.62
6810.85
6968.55
6885.74
6826.74
6836.83
6863.71
6908.17
6808.26
6868.55
7005.63
6921.88
7095.23
7004.62
7012.23
7003.74
6983.32
7084.52
7081.7
7170.41
7139.58
7195.82
7145.06
7200.66
7299.74
7293.26
7255.01
7302.05
7236.72
7321.66
7269.32
7360.95
7336.82
7356.97
7403.55
7457.83
7584.5
7471.67
7446.34
7567.64
7667.84
7698.02
7538.93
7530.92
7759.22
7729.04
7716.4
7724.58
7945.34
7905.21
7856.25
7895.77
7819.72
7880.47
7912.08
7843.6
7915.2
8086.81
8034.12
8072.36
8179.04
8272.57
8148.85
8201.47
8220.06
8155.12
8393.21
8135.74
8257.34
8393.72
8419.53
8409.5
8323.1
8496.3
8483.16
8656.13
8700.85
8775.87
8860.75
8847.83
8798.52
8776.79
8807.82
8796.75
8913.13
8909.93
8862.21
8997.43
9033.31
9077.97
9107.42
9062.8
9075.65
9132.03
9319.31
9481.35
9361.27
9413.42
9371.67
9285.53
9613.19
9598.6
9568.31
9697.87
9599.73
9461.42
9668.24
9903.49
9980.71
10014.8
9892.01
9855.36
9956.75
9954.02
10125.7
9921.8
10164.1
10174.4
10158.5
10166.7
10128.3
10152.4
10095.9
9852.76
9962.69
9874.38
9982.46
10063.3
9875.26
9945.61
10253
10801.4
11694.1
12978.2
13037.5
11676.6
10569
10285.3
10089.4
9790.86
9667.26
9535.2
9383.1
9177.72
8887.76
8586.78
8456.76
8493.29
8599.87
8716.4
8945.73
9624.36
11973.8
15600.3
14567.7
10708.3
8456.71
7967.36
7829.3
7872.02
7781.62
7805.18
7792.33
7756.98
7757.89
7483.55
7716.22
7996.52
7946.83
7969.49
7858.5
7888.09
7936.72
7958.06
7916.29
7951.35
8021.91
7888.83
7872.41
8145.86
8046.55
8080.45
8253.66
8290.44
8381.59
8348.42
8361
8414.48
8281.86
8301.59
8315.41
8282.76
8009.29
7852.58
7937.6
7839.68
7679.39
7754.05
7717.51
7695.31
7842.34
7749.11
7885.27
7872.41
7843.6
7748.58
7634.31
7613.49
7774.25
7888.69
7891.34
7858.47
7860.94
7936.4
8019.09
8137.79
8002.07
7994.38
8042.81
7934.53
7976.41
8133.71
8150.24
8150.56
8054.47
8118.38
8223.85
8111.84
8037.53
8318.89
8251.21
8311.98
8464.84
8450.49
8484.77
8591.77
8584.76
8616.84
8566.43
8503.02
8374.68
8336.76
8249.02
8173.74
8240.88
8266.77
8281.45
8327.77
8460.12
8394.29
8265
8048.07
8219.43
8358.11
8398.7
8453.79
8489.36
8510.88
8453.12
8580.09
8582.38
8708.08
8642.55
8636.75
8616.89
8724.26
8742.6
8611.05
8697.94
8711.64
8720.18
8820.96
8930.63
8772.4
8780.15
8771.62
8665.49
8933.58
8862.63
8979.94
8836.23
8976.73
9085.19
9129.89
9153.8
9176.45
9033.06
9018.28
8929.04
9189.78
9093.76
9154.95
9246.93
9139.98
9305.54
9273.72
9307
9398.85
9428.46
9315.71
9366.49
9233.5
9353.41
9368.42
9409.02
9563.93
9656.46
9552.33
9557.31
9617.55
9771.48
9767.28
10037.3
9863.56
9846.8
9836.96
9904.49
9885.36
9823.2
9903.58
9836.03
9821.43
9589.53
9605.88
9675.63
9751.77
9741.88
9661.5
9743.24
9682.52
9682.56
9684.9
9759.18
9923.12
9728.52
9712.02
9817.62
9689.6
9863.8
9842.04
9548.53
9916.01
9962.16
10021.3
10178.6
9954.21
10110
10102.3
10076.3
9859.72
10062.9
9984.14
9969.44
10223.7
10156.3
10266.1
10236.2
10373.7
10484.5
10596.1
10404.7
10207.2
10351.8
10483.9
10558.9
10492.5
10503.9
10692
10777.6
10751
10438.7
10318.5
10641.1
10743.7
10601.5
10576.4
10465.7
10330.1
10168.3
10199.7
10194.4
10064.9
10174.6
10101.8
9858.5
10053.3
10173
10079
10133.9
10148.4
10001.3
9967.7
10144
10347.7
10338.5
10146.1
10177.7
10230.4
10090.5
10203
10275.9
10239.5
10316.8
10323.6
10354.4
10277.3
10309.3
10539.7
10590
10708.4
10606.2
10380.6
10599.9
10638.8
10764.8
10966.4
10972
11040.3
11088.4
11090.6
11015.9
11148.1
11240.1
11269.8
11238
11283.1
11461
11390.6
11576.7
11854.5
11565
11620.8
11651.6
11740.7
11944.4
12241.3
12178.8
11926.7
12075.8
11802.8
11616.1
11332.7
11473.8
11431.7
11512.2
11692.9
11979.2
11692.2
10772.3
9874.91
9344.27
8927.02
8801.92
8761.18
8786.48
8722.73
8740.69
8656.55
8860.72
8850.95
8815.64
8519.09
8556.66
8631.07
8690.05
8593.1
8634.02
8576.96
8788.02
8577.76
8588.97
8681.44
8611.25
8578.34
8567.42
8640.11
8677.3
8785
8670.16
8623.3
8494.9
8700.85
8789.14
8828.59
8793.64
8841.07
8984
8933.25
9159.09
8987.38
8976.55
9068.54
9076.57
9242.32
9093.3
9175.12
9181.79
9204.34
9335.21
9415.4
9190.92
9151.72
9054.79
9132.78
9201.56
9264.86
9081.61
9133.05
9145.94
9385.58
9246.02
9415.22
9547.24
9849.66
9938.03
10245.5
10663
11035.9
11421.3
10900.3
9834.45
9277.05
8456.54
8155.99
8176.9
8032.02
7926.6
7899.11
7992.54
7949.34
7910.81
7762.69
7911.26
7922.39
7920.58
7739.84
8129.49
8126.96
8331.84
8208.88
7889.91
7616.66
7664.44
7554.77
7561.13
7562.73
7678.09
7498.37
7961.56
7850.37
7821.58
7872.37
7842.17
7801.87
7829.74
7878.04
7891.31
7757.59
7596.72
7545.52
7602.38
7610.86
7758.57
7653.49
7888.89
7890.43
7931.2
8030.74
7953.48
8104.83
8070.48
8069.74
7998.77
7792.6
7548.95
7423.27
7496
7523.33
7575.27
7643.86
7815.63
7960.89
7655.84
7689.37
7607.5
7624.41
7514.2
7500.33
7496.5
7533.89
7464.63
7506.51
7495.71
7516.06
7453.88
7581.35
7582.47
7867
7931.77
7820.37
7856.13
7757.2
7755.87
7692.93
7682.24
7810.13
7729.08
7752.47
7769.15
7657.35
7626.55
7740.08
7598.96
7774.35
7876.21
7817.65
8067.56
7966.03
8061.41
8153.43
8142.69
7998.97
7981.27
7947.8
7897.6
7904.02
8082.27
8199.6
8353.75
8252.93
8279.78
8026.6
7735.43
7532.25
7419.84
7330.2
7174.89
7202.31
7128.56
7187.73
7130.48
7053.65
7080.2
7205.35
7298.73
7182.52
7459.08
7464.88
7515.09
7554.65
7754.71
7598.27
7537.73
7442.13
7502.8
7455.61
7383.04
7417.05
7228.34
7231.61
7217.29
7179.69
7327.63
7292.7
7313.99
7656.74
8155.83
7825.55
7200.83
7009.67
6773.82
6510.2
6312.7
6317.66
6274.42
6325.09
6131.86
6105.67
6268.1
6171.34
6203.41
6201.39
6114.77
6155.14
6137.84
6158.47
6285.04
6283.31
6282.87
6466.5
6541.22
6479.6
6907.05
7186.58
7014.69
6746.73
6689.61
6526.36
6554.01
6387
6356.23
6381.71
6271.46
6429.18
6419.2
6474.19
6255.27
6434.87
6576.14
6544.23
6582.52
6842.33
6966.96
7238.36
7417.51
7773.86
7888.51
7759.55
7311.31
6815.9
6401.63
6413
6370.19
6351.97
6437.35
6811.27
6933.71
6946.52
7079.06
6690.7
6317.47
5943.02
5826.04
5641.61
5481.2
5285.46
5318.04
5386.43
5136.74
5112.42
5225.23
5204.59
5216.6
5186.78
5246.77
5259.59
5167.76
5244.22
5544.8
5720.07
5980.1
6200.85
6233.11
6143.01
5740.5
5463.12
5319.88
5113.36
5069.16
5170.68
5246.11
5072.88
5127.95
4929.85
4889.64
4887.29
4871.96
4841.28
4721.38
4661.29
4678.55
4774.81
4778.33
4801.76
4766.98
4966.06
5091.25
4974.44
4935.3
5078.72
4838.39
4975.03
5008.37
4987.02
4958.15
4886.19
4933.98
4961.11
4996.7
5019.58
5056.21
5120.73
5179.36
5225.58
5280.86
5284.16
5331.95
5429.84
5515.64
5543.85
5722.06
6122.57
6318.83
6032.29
6014.31
6140.66
6122.56
6386.68
6323.98
6398.03
6260.24
6167.74
5985.91
5912.26
5847.5
5761.53
5744.53
5859.38
5911.69
6205.79
6384.77
6674.36
7010.71
7767.55
9178.97
11038.6
11817.4
10058.9
8023.03
7102.04
6650.8
6008.05
4925.07
4138.03
3749.69
3679.29
3686.41
3735.45
3719.84
3773.72
3803.87
3699.25
3715.48
3785.16
3847.11
3758.09
3715.25
3776.57
3770.89
3706.01
3657.55
3634.18
3635.54
3629.37
3690.35
3754.28
3766.3
3978.06
4329.27
4863.76
5586.45
6747.39
6652.01
5486.04
4457.12
3845.83
3592.02
3077.35
2822.45
2599.12
2641.87
2533.12
2563.74
2519.8
2603.52
2713.95
2608.49
2687.68
2740.85
2763.25
2874.76
2956.05
3174.26
2958.59
2711.28
2419.68
2309.44
2272.5
2310.46
2286.9
2182.56
2096.77
2228.48
2270.75
2243.76
2351.76
2229.59
2264.94
2339.37
2328.52
2445.88
2346.55
2315.95
2227.77
2207.51
2199.12
2263.2
2314.38
2335.91
2454.2
2450.93
2479.58
2507.7
2506.03
2411.08
2374.4
2380.96
2423.07
2422.67
2365.31
2456.7
2421.2
2515.02
2556.04
2645.99
2737.29
2807.02
2761.75
2693.07
2512.91
2399.19
2380.27
2348.31
2414.08
2446.38
2380.93
2488.98
2531.73
2592.49
2843.07
3036.08
3305.06
3316.42
3091.87
3090.33
3417.45
3776.78
3473.33
2809.84
2176.44
1871.34
1741.62
1613.68
1702.86
1625.27
1606.44
1760.42
1856.77
1927.37
1820.53
1714.44
1784.07
1938.48
2046.17
2007.51
1805.39
1646.31
1574.41
1532.96
1440.26
1445.15
1417.04
1371.24
1371.81
1380.57
1498.75
1513.47
1620.1
1706.17
1661.37
1674.18
1743.44
1813.17
1715.61
1543.99
1421.49
1387.29
1338.07
1384.93
1402.29
1462.25
1440.35
1367.64
1412.6
1469.03
1368.07
1365.37
1340.34
1327.52
1337.4
1338.87
1355.54
1344.15
1393.11
1437.46
1463.22
1445.2
1689.01
1887.33
2066.4
2180.74
2131.01
1797.11
1399.61
1259.01
1104.87
1075.79
1084.59
1054.09
978.038
986.918
954.093
1054.37
1056.87
1069.42
1021.11
980.71
1037.11
943.2
967.459
994.962
923.988
922.021
964.719
928.231
925.525
1031.74
1028.9
1189.47
1225.93
1036.59
890.794
926.768
1129.08
1750.06
2388.59
1927.62
1043.65
534.786
450.057
431.797
416.608
401.937
365.55
367.424
348.639
369.886
364.093
333.744
340.611
334.468
309.666
356.221
373.918
386.271
415.588
586.903
772.777
618.276
391.205
296.648
254.206
241.931
299.779
313.639
256.547
249.486
248.958
248
314.072
412.903
584.713
727.316
703.781
557.824
361.417
175.673
56.2299
19.8585
9.44247
3.16834
4.94825
6.90255
1
end of experiment