File: Vms/Experiment 2022-06-01_CuMnAs_16_VB4.vms
VAMAS Surface Chemical Analysis Standard Data Transfer Format 1988 May 4
Specs
PHOIBOS HSA3500 DLD 150 R7[HWType 30:101] DLD
ppxcf1
?
1
Created by SpecsLab Prodigy, Version 4.91.3-r105809
NORM
REGULAR
1
0
0
0
0
0
1
VB4
Transmission cyclic
2022
6
1
13
22
5
0
9
File = C:/Users/ppxcf1/Desktop/Data/XPS/01-Jun-2022/Experiment 2022-06-01_CuMnAs (1).sle
Group = Transmission cyclic
First of group = 1
Spectrum ID = 16
Analyzer lens = SmallArea:1.5kV
Analyzer slit = 4:7x20c\B:open
Scan mode = FixedAnalyzerTransmission
Kinetic energy start = 1456.61
OrdinateRange = [-22.000000, 22.000000]
XPS
Al
1486.61
0
0
0
54.500000
180.000000
FAT
20
1
4.14
0
0
0
0
0
VB4

-1
kinetic energy
eV
1456.61
0.1
2
counts
d
Transmission
d
pulse counting
0.5
10
0
0
0
0
0
622
18.9653
962.782
1
1
229.028
1
225.381
1
224.752
1
220.986
1
212.523
1
216.397
1
245.606
1
247.604
1
214.999
1
209.16
1
258.526
1
237.667
1
218.485
1
231.376
1
226.691
1
229.071
1
246.636
1
254.828
1
221.071
1
228.422
1
247.016
1
227.92
1
245.006
1
279.33
1
258.982
1
254.507
1
238.811
1
223.907
1
243.584
1
244.974
1
252.931
1
246.503
1
209.894
1
236.117
1
237.15
1
258.197
1
269.849
1
250.159
1
266.133
1
252.548
1
242.478
1
238.139
1
232.312
1
219.042
1
214.696
1
228.571
1
221.599
1
251.219
1
257.863
1
248.049
1
251.683
1
241.822
1
240.097
1
228.603
1
234.894
1
227.978
1
229.103
1
223.754
1
216.49
1
218.57
1
241.536
1
239.521
1
232.008
1
238.201
1
233.739
1
217.044
1
197.979
1
221.038
1
221.535
1
208.409
1
236.011
1
219.86
1
228.808
1
226.496
1
218.744
1
257.98
1
238.304
1
229.881
1
225.463
1
219.318
1
246.094
1
237.262
1
240.545
1
232.997
1
251.172
1
304.247
1
270.096
1
252.988
1
268.635
1
278.401
1
292.205
1
318.84
1
397.888
1
415.191
1
524.557
1
584.768
1
702.796
1
801.683
1
868.703
1
915.401
1
938.778
1
959.575
1
962.782
1
822.041
1
762.643
1
652.825
1
564.651
1
456.771
1
377.512
1
301.371
1
279.74
1
276.107
1
226.017
1
215.295
1
222.073
1
218.287
1
210.52
1
200.954
1
186.837
1
182.051
1
218.916
1
206.991
1
202.744
1
213.131
1
227.489
1
239.389
1
208.853
1
168.49
1
202.145
1
210.3
1
207.716
1
202.952
1
203.268
1
181.95
1
195.532
1
198.698
1
176.491
1
184.515
1
177.416
1
161.595
1
158.287
1
180.317
1
173.188
1
172.39
1
198.827
1
172.876
1
167.973
1
171.85
1
182.239
1
165.208
1
166.428
1
179.733
1
181.872
1
169.302
1
155.801
1
171.862
1
171.205
1
199.441
1
157.917
1
158.555
1
161.631
1
176.037
1
179.692
1
193.092
1
192.049
1
198.456
1
206.292
1
214.081
1
213.217
1
206.62
1
200.922
1
201.053
1
178.536
1
190.048
1
188.994
1
212.852
1
187.307
1
198.887
1
186.035
1
196.884
1
211.666
1
195.209
1
193.204
1
191.992
1
196.284
1
183.214
1
177.68
1
167.167
1
160.825
1
152.736
1
153.487
1
141.262
1
145.729
1
128.629
1
155.663
1
143.608
1
144.101
1
137.966
1
132.149
1
126.322
1
120.275
1
132.192
1
135.461
1
124.62
1
129.424
1
141.901
1
134.928
1
131.007
1
149.174
1
153.045
1
151.835
1
137.573
1
138.62
1
149.897
1
142.484
1
145.793
1
171.687
1
156.225
1
172.658
1
172.601
1
178.468
1
190.498
1
198.935
1
192.39
1
183.137
1
204.768
1
203.242
1
213.138
1
230.309
1
238.875
1
250.079
1
246.186
1
240.119
1
261.364
1
270.985
1
287.563
1
275.886
1
280.613
1
319.389
1
339.182
1
325.422
1
376.762
1
406.201
1
423.548
1
458.064
1
505.716
1
520.434
1
559.914
1
609.546
1
715.213
1
718.796
1
713.32
1
748.527
1
790.286
1
793.699
1
823.375
1
795.287
1
788
1
792.469
1
745.093
1
695.285
1
715.028
1
650.079
1
611.486
1
555.706
1
518.742
1
436.743
1
369.712
1
347.805
1
346.193
1
352.575
1
331.648
1
313.755
1
290.008
1
281.811
1
301.691
1
302.82
1
275.864
1
239.435
1
264.895
1
220.588
1
225.682
1
194.239
1
205.498
1
196.124
1
179.416
1
155.186
1
136.457
1
157.709
1
154.182
1
123.903
1
120.155
1
113.039
1
90.7748
1
90.0965
1
64.8743
1
56.3199
1
50.4061
1
24.5424
1
24.862
1
23.1095
1
31.084
1
31.2501
1
18.9653
1
25.5563
1
29.1445
1
26.7869
1
32.0716
1
29.108
1
24.7105
1
32.3202
1
end of experiment