File: Vms/Experiment 2022-06-01_CuMnAs_7_Wide3.vms
VAMAS Surface Chemical Analysis Standard Data Transfer Format 1988 May 4
Specs
PHOIBOS HSA3500 DLD 150 R7[HWType 30:101] DLD
ppxcf1
?
1
Created by SpecsLab Prodigy, Version 4.91.3-r105809
NORM
REGULAR
1
0
0
0
0
0
1
Wide3
Transmission cyclic
2022
6
1
9
47
32
0
9
File = C:/Users/ppxcf1/Desktop/Data/XPS/01-Jun-2022/Experiment 2022-06-01_CuMnAs (1).sle
Group = Transmission cyclic
First of group = 1
Spectrum ID = 7
Analyzer lens = SmallArea:1.5kV
Analyzer slit = 4:7x20c\B:open
Scan mode = FixedAnalyzerTransmission
Kinetic energy start = 386.61
OrdinateRange = [-22.000000, 22.000000]
XPS
Al
1486.61
0
0
0
54.500000
180.000000
FAT
100
1
4.14
0
0
0
0
0
Wide3

-1
kinetic energy
eV
386.61
1
2
counts
d
Transmission
d
pulse counting
0.1
0
0
0
0.614107
1
4698.74
4812.22
4861.79
4850.24
4853.16
4777.48
4682.78
4555.6
4653.41
4676.53
4867.98
4696.32
4562.35
4479.62
4561.76
4701.32
4712.32
4662.9
4642.21
4632.98
4766.91
4666.24
4661.61
4710.88
4638.17
4822.8
4780.11
4747.52
4881.81
4868.21
4741.52
4861.34
4823.87
4768.38
4787.94
4871.48
4824.39
4895.1
4915.33
4848.63
4951.86
5012.72
5004.7
5011.27
4907.46
5102.69
5063.88
4981.42
5057.4
5076.34
5062.67
5079.21
5069.82
5206.86
5233.06
5144.88
5143.84
5157.66
5134.07
5247.38
5240.63
5292.59
5316.32
5284.83
5304.25
5483.35
5295.68
5420.67
5359.16
5503.42
5389.15
5381.76
5348.59
5343.56
5441.52
5585.9
5690.42
5627.86
5649.68
5460.26
5669.99
5719.57
5738.09
5679.86
5768.55
5763.39
5694.86
5646.91
5686.89
5649.85
5820.52
5920.5
5944.83
5833.45
5907.74
5885.3
6028.37
6022.74
5942.74
5983.61
5981.52
6049.66
6242.56
6122.39
6086.95
6267.72
6223.58
6297.63
6269.59
6426.67
6529.4
6461.81
6462.56
6294.67
6257.92
6439.26
6265.31
6321.2
6421.67
6536.26
6620.38
6477.41
6398.21
6658.12
6551.29
6724.69
6676.27
6704.38
6703.23
6767
6917.45
6741.73
6725.04
6804.14
6891.75
6885.92
6735.54
6689.38
6597.88
6573.06
6761.76
6773.28
6851.46
6981.71
7284.43
7877.97
8950.36
9107.44
7979.12
7307.75
6966.41
6892.46
6782.4
6561.29
6445.64
6313.42
6352.54
6174.65
5909.71
5821.25
5781.44
5666.94
5905.78
6112.56
6752.79
8287.2
11021.2
10223.2
7425.5
5816.75
5318.55
5367.63
5368.36
5314.39
5362.59
5281.75
5309.8
5284.87
5390.68
5310.2
5386.71
5394.63
5230.44
5354.14
5385.75
5339.58
5363.09
5460.49
5435.74
5327.84
5475.4
5475.1
5633.99
5587.19
5481.83
5613.53
5739.95
5690.41
5757.32
5802.38
5763.22
5871.74
5822.55
5717.27
5716.65
5511.88
5397.89
5301.7
5414.68
5329.63
5328.97
5355.25
5185.44
5261.72
5260.48
5272.67
5280.01
5294.97
5273.87
5377.92
5374.78
5429.96
5414.65
5381.59
5418.15
5360.7
5544.74
5454.74
5440.94
5343.03
5450.03
5477.74
5430.94
5562.51
5608.09
5557.38
5446.43
5499.95
5562.53
5625.75
5527.96
5567.53
5629.89
5491.23
5676.45
5777.91
5789.58
5827.49
5904.69
5892.98
5838.13
5930.43
5731.16
5717.03
5655.66
5741.12
5700.03
5764.56
5627.67
5790.67
5597.63
5603.21
5784.99
5789.44
5738.78
5709.28
5806.71
5700.92
5696.37
5785.46
5796.53
5862.74
5715.6
5781.72
5856.2
5878.34
5935.93
5766.77
5869.67
5842.41
5894.67
5880.14
6015.92
6120.41
5998.21
5952.29
5988.69
6036.45
6000.05
5962.11
6065.74
5998.35
6043.07
6082.86
6179.66
6139.48
6175.59
6185.92
6246.2
6258.58
6250.21
6142.01
6319.45
6343.27
6274.81
6295.28
6234.99
6289.2
6366.77
6296.99
6307.29
6395.51
6331.28
6334.66
6377.9
6395.18
6435.51
6489.55
6648.46
6606.82
6316.08
6296.39
6608.93
6690.01
6694.42
6552.72
6697.15
6666.88
6618.6
6761.03
6873.62
6870.52
6764.18
6805.15
6785.55
6519.14
6437.7
6434.09
6583.35
6614.39
6648.22
6551.08
6416.32
6469.05
6569.74
6572.53
6535.42
6545.86
6624.18
6731.87
6604.77
6662.8
6718.43
6760.14
6725.21
6855.98
6882.97
6855.75
6826.96
6826.35
6942.74
6786.37
6907.61
6918.83
7042.11
6865.92
6941.85
7035
6921.36
7003.13
7125.24
6989.51
6894.32
7041.78
6994.34
7049.54
7093.91
7214.46
7141.18
7180.38
7052.81
7221.41
7035.01
7153.58
7150.99
7133.52
7206.4
7179.06
7209.44
6977.48
7107.29
6989.54
6986.4
6925.97
6935.4
6887.54
6785.25
6850.57
6823.08
6853.44
6909.66
6949.82
6979.47
6839.3
6980.73
6963
6937.61
6861.67
6912.05
7155.49
7052.66
6948.08
6911.94
7092.58
7106.85
6980.07
7069.23
7186.31
7056.83
7221.04
7365.49
7381.41
7271.98
7398.87
7289.89
7329.85
7380.85
7501.21
7639.61
7547.21
7545.86
7462.83
7725.79
7645.43
7679.82
7784.15
7786.37
7700.63
7942.3
7885.97
7901.98
8159.25
8202.37
8038.06
8117.12
8093.48
8147.26
8220.29
8376.76
8445.2
8317.61
8374.92
8376.09
8283.4
8148.77
8015.08
8104.07
8101.88
8282.85
8382.45
8432.45
7606.95
6989.14
6640.89
6219.05
6128.94
6253.55
6169.72
6216.6
6304.92
6405.21
6220.84
6138.26
6242.69
6084.43
6083.36
6119.37
6115.17
6017.29
6220.66
6304.46
6138.59
6133.76
6062.7
6209.64
6233.24
6149.42
6311.49
6138.78
6162.83
6178.67
6243.17
6190.22
6418.64
6365.15
6259.67
6231.21
6182.76
6110.49
6323.14
6386.08
6355.08
6412.39
6441.2
6485.55
6501.8
6528.62
6664.99
6559.79
6651.45
6714.67
6669.03
6598.99
6549.28
6586.16
6491.62
6464.18
6483.51
6421.4
6451.06
6370.54
6399.5
6474.38
6476.54
6543.42
6774.27
6944.15
7097.28
7239.76
7341.98
7688.38
8018.3
7415.63
6790.99
6479.51
6007.47
5883.41
5809.69
5694.22
5687.01
5659.69
5680.52
5620.86
5474.07
5604.44
5572.66
5749.97
5570.68
5625.9
5763.9
5856.74
5781.45
5670.51
5597.64
5448.56
5503.89
5519.75
5388.53
5454.22
5363.29
5414.86
5602.56
5636.06
5491.06
5603.08
5723.83
5773.81
5744.18
5616.68
5742.24
5475.92
5429.82
5453.26
5444.62
5389.27
5470.69
5582.24
5625.7
5749.86
5633.42
5713.08
5853.9
5888.92
5913.2
5964.9
5870.15
5778.74
5454.02
5479.51
5420.02
5397.31
5406.14
5572.69
5669.05
5657.74
5613.06
5568.69
5485.46
5497.73
5380.16
5260.63
5308.79
5259.34
5265.32
5293.04
5189.58
5069.93
5160.85
5222.29
5326.25
5262.57
5456.16
5461.26
5331.98
5370.17
5176.22
5183.39
5393.91
5369.58
5329.89
5355.12
5381.67
5342.08
5308.88
5236.21
5228.95
5409.26
5413.38
5382.32
5292.39
5324.08
5498.57
5532.32
5531.49
5539.34
5605.1
5422.55
5526.21
5383.39
5458.02
5592.1
5576.26
5518.4
5585.38
5542.74
5406.94
5268.14
5212.85
5025.74
5003.02
4963.04
4878.56
5015.14
4938.18
4990.33
4989.39
4995.2
5045.3
5243.05
5231.87
5261.58
5379.7
5441.16
5449.75
5460.47
5346.45
5271.33
5343.77
5267.22
5178.27
5120.58
5034.77
5023.87
5048.51
5208.64
5248.54
5177.81
5405.27
5723.98
6318.5
6078.02
5442.41
5129.43
4962.56
4754.71
4274.65
4259.75
4274.99
4169.06
4183.95
4202.99
4138.08
4049.37
4089.41
4064.2
3957.64
4132.46
4113.68
3974.25
4079.37
4030.43
4159.93
4164.77
4143.48
4267.06
4631.32
4840.2
4825.15
4578.29
4404.77
4408.18
4118.1
4126.73
4080.31
3917.83
3897.76
3990.21
4035.18
3923
3928.91
4016.98
4096.04
3959.41
3989.55
4144.62
4336.43
4442.15
4668.47
4867.21
4869.28
4866.54
4593.31
4258.83
4081.92
3947.54
3939.27
3979.99
3948.47
4183.44
4347.96
4441.01
4400.12
4264.81
3920.47
3877.1
3580.22
3505.38
3383.14
3367.51
3244.59
3260.86
3261.87
3247.79
3200.82
3222.05
3282.34
3200.32
3170.77
3260.45
3258.49
3236.55
3391.7
3543.3
3681.3
3865.53
4035.65
3880.35
3699.05
3434.49
3419.72
3238.77
3241.89
3199.95
3314.51
3217.94
3190.45
3207.32
3114.61
3038.51
2923.44
3050.77
2990.36
2985.29
2973.58
3019.69
2894.06
3021.46
3152.43
3080.16
3055.8
3080.47
3082.82
3085.44
3126.14
3097.04
3105.14
3090.36
3116.51
3066.74
3173
3128.65
3180.25
3217.57
3218.73
3145.35
3186.19
3205.76
3260.41
3145.42
3290.09
3393.4
3400.44
3347.92
3493.46
3667.5
3751.67
3744.26
3684.62
3747.56
3838.74
3832.55
3804.72
3888.7
3827.24
3916.65
3755.8
3722.72
3674.09
3620.95
3663.16
3612.76
3648.5
3780.72
3996.42
4057.64
4370.56
4824.35
5575.52
7015.16
7588.43
6620.92
5174.53
4529.72
4435
3922.4
3155.62
2620.63
2566.04
2525.87
2343.54
2287.84
2388.9
2432.46
2398.34
2457.2
2420.02
2489.01
2503.93
2481.79
2500.84
2416.12
2430.49
2435.74
2348.16
2401.52
2387.23
2352.78
2425.84
2555.17
2521.37
2592.13
2755.65
3125.09
3654.92
4168.45
4157.87
3625.47
3063.09
2655.41
2429.38
2149.84
1983.89
1868.87
1748.8
1754.48
1791.33
1810.57
1808.8
1850.07
1827.32
1815.12
1918.46
1984.04
2051.12
2140.76
2229.8
2204.18
2053.9
1771.29
1659.51
1700.37
1632.23
1640.46
1597.71
1587
1556.2
1605.23
1546.21
1587.1
1715.68
1665.63
1670.7
1905.3
1973.83
1898.5
1725.01
1630.77
1627.35
1681.84
1695.48
1776.95
1725.61
1726.38
1698.71
1668.5
1746.41
1732.85
1681
1658.11
1696.76
1691.84
1715.88
1754.55
1709.56
1782.37
1782.16
1889.55
1937.12
2005.46
2080.38
2092.74
1967.59
1844.52
1770
1689.9
1809.94
1784.95
1706.42
1721.79
1742.94
1792.81
1804.57
1997.04
2214.26
2441.24
2484.66
2352.1
2364.58
2525.59
2686.9
2552.47
2055.88
1642.88
1453.97
1280.03
1268.14
1202.14
1278.09
1311.53
1436.77
1680.06
1621.01
1428.06
1393.94
1343.79
1492.14
1554.01
1529.18
1400.11
1236.61
1147.07
1065.93
1030.58
992.215
1046.39
1001.27
985.711
1033.61
1058.66
1126.09
1219.34
1398.83
1449.04
1497.38
1554.54
1591.86
1385.01
1189.82
1079.25
946.93
964.912
936.16
916.432
973.932
899.018
963.259
895.918
907.73
918.05
942.538
918.011
893.647
879.546
841.422
830.206
891.496
911.07
952.751
974.517
1042.68
1106.99
1233.58
1413.65
1480.06
1510.43
1277.42
995.824
805.086
735.991
734.036
703.048
718.167
687.216
718.722
732.942
715.453
683.354
674.791
650.315
699.74
677.111
664.915
648.068
653.196
664.449
656.185
678.707
696.059
719.814
728.467
754.133
809.416
852.766
772.459
664.163
636.597
759.758
1213.68
1674.87
1435.7
788.342
467.569
376.798
409.695
377.885
357.742
345.534
302.685
293.728
256.072
248.398
222.07
262.508
250.642
246.908
268.895
307.639
312.035
355.228
582.777
855.643
708.958
353.169
204.833
179.245
195.238
166.918
185.51
185.845
167.774
168.639
163.896
239.43
329.459
415.83
564.874
567.811
421.416
240.33
145.762
51.4519
10.4534
7.7016
1.63935
1.24618
0.614107
1
end of experiment