File: Vms/Experiment 2022-06-01_CuMnAs_8_Cu2p3.vms
VAMAS Surface Chemical Analysis Standard Data Transfer Format 1988 May 4
Specs
PHOIBOS HSA3500 DLD 150 R7[HWType 30:101] DLD
ppxcf1
?
1
Created by SpecsLab Prodigy, Version 4.91.3-r105809
NORM
REGULAR
1
0
0
0
0
0
1
Cu2p3
Transmission cyclic
2022
6
1
9
58
53
0
9
File = C:/Users/ppxcf1/Desktop/Data/XPS/01-Jun-2022/Experiment 2022-06-01_CuMnAs (1).sle
Group = Transmission cyclic
First of group = 1
Spectrum ID = 8
Analyzer lens = SmallArea:1.5kV
Analyzer slit = 4:7x20c\B:open
Scan mode = FixedAnalyzerTransmission
Kinetic energy start = 511.61
OrdinateRange = [-22.000000, 22.000000]
XPS
Al
1486.61
0
0
0
54.500000
180.000000
FAT
20
1
4.14
0
0
0
0
0
Cu2p3

-1
kinetic energy
eV
511.61
0.1
2
counts
d
Transmission
d
pulse counting
0.1
10
0
0
0
0
0
1002
5365.08
17538.4
1
1
7657.05
1
7469.82
1
7484.26
1
7494.78
1
7644.26
1
7409.69
1
7532.71
1
7505.17
1
7379.13
1
7418.18
1
7518.67
1
7614.63
1
7482.63
1
7511.99
1
7559.19
1
7562.87
1
7638.19
1
7513.39
1
7346.9
1
7409.09
1
7484.77
1
7457.41
1
7455.88
1
7402.06
1
7453.05
1
7558.99
1
7510.05
1
7494.44
1
7426.58
1
7522.14
1
7546.22
1
7442.53
1
7525.99
1
7540.46
1
7581.49
1
7547.93
1
7630.99
1
7484.19
1
7577.7
1
7697.74
1
7604.28
1
7621.43
1
7627.16
1
7469.08
1
7608.41
1
7432.05
1
7376.67
1
7586.72
1
7662.13
1
7653.74
1
7482.02
1
7611.23
1
7654.86
1
7560.48
1
7619.63
1
7578.97
1
7456.72
1
7628.74
1
7542.53
1
7665.92
1
7603.15
1
7480.4
1
7574.02
1
7660.89
1
7683.66
1
7488.53
1
7571.02
1
7465.21
1
7482.78
1
7591.41
1
7520.36
1
7557.05
1
7651.4
1
7600.81
1
7680.25
1
7561.92
1
7541.07
1
7515.52
1
7663.44
1
7474.72
1
7559.8
1
7459.94
1
7452.48
1
7508.22
1
7648.33
1
7541.4
1
7558.41
1
7558.7
1
7513.59
1
7504.86
1
7511.85
1
7497.66
1
7491.79
1
7448.88
1
7473.62
1
7430.09
1
7528.38
1
7489
1
7381.67
1
7540.63
1
7427.09
1
7390.63
1
7290.78
1
7315.47
1
7408.3
1
7292.42
1
7212.17
1
7297.72
1
7300.01
1
7357.32
1
7350.05
1
7327.96
1
7341.29
1
7271.85
1
7259.92
1
7353.33
1
7346.35
1
7319.67
1
7285.77
1
7392.23
1
7426.55
1
7436.2
1
7351.49
1
7365.51
1
7233.37
1
7291.33
1
7367.38
1
7426.05
1
7351.29
1
7147.88
1
7324.51
1
7347.72
1
7343.7
1
7397.7
1
7336.17
1
7291.8
1
7189.76
1
7321.68
1
7329.75
1
7320.89
1
7302.1
1
7141.27
1
7207.74
1
7294.19
1
7291.52
1
7326.95
1
7386.15
1
7425.08
1
7371.91
1
7370
1
7336.15
1
7321.53
1
7296.47
1
7362.59
1
7268.91
1
7381.12
1
7177.91
1
7374.7
1
7472.39
1
7405.66
1
7364.82
1
7437.28
1
7369.99
1
7463.41
1
7367.77
1
7392.44
1
7482.21
1
7358.46
1
7350.51
1
7302.48
1
7347.93
1
7357.42
1
7480.03
1
7474.96
1
7553.52
1
7557.07
1
7448.15
1
7525.64
1
7472.13
1
7450.31
1
7521.28
1
7703.14
1
7538.05
1
7547.97
1
7678.14
1
7669.38
1
7669.05
1
7539.09
1
7654.36
1
7739.49
1
7771.94
1
7704.94
1
7909.65
1
7757.66
1
7901.24
1
7989.15
1
8105.43
1
8093.88
1
8179.72
1
8227.67
1
8190.36
1
8365.1
1
8593.98
1
8753.33
1
8878.7
1
9067.07
1
9275.22
1
9459.04
1
9583.55
1
9977.97
1
10354.2
1
10580.6
1
10702.8
1
11180.1
1
11502.1
1
11665.5
1
11511.1
1
11483.6
1
11343.8
1
11180
1
10803.6
1
10564.8
1
10256.4
1
9815.37
1
9473.7
1
9194.44
1
8868.31
1
8816.65
1
8552.06
1
8398.04
1
8125.74
1
8100.37
1
8040.46
1
8037.45
1
7934.66
1
7782.84
1
7814.75
1
7563.95
1
7723.92
1
7553.62
1
7461.63
1
7472.43
1
7626.11
1
7634.81
1
7551.3
1
7434.27
1
7363.31
1
7424.32
1
7559.96
1
7360.08
1
7295.3
1
7352.06
1
7333.45
1
7314.9
1
7398.77
1
7371.17
1
7458.36
1
7446.2
1
7508.29
1
7404.3
1
7399.57
1
7308.84
1
7335.06
1
7476.22
1
7242.3
1
7288.33
1
7110.19
1
7145.38
1
7355.53
1
7174.68
1
7172.61
1
7259.93
1
7347.92
1
7291.74
1
7139.89
1
7104.48
1
7158.14
1
7197.33
1
7138.13
1
7079.6
1
7022.69
1
7180.48
1
7110.96
1
7095.61
1
6992.49
1
7020.33
1
6974.52
1
6951.28
1
6997.28
1
7051.44
1
6853.16
1
6947.95
1
6965.98
1
6984.26
1
6932.06
1
6867.61
1
6848.08
1
6989.81
1
6934.51
1
6736.48
1
6798.89
1
6759.93
1
6628.33
1
6821.4
1
6787.84
1
6813.54
1
6766.49
1
6751.68
1
6666.76
1
6778.2
1
6682.28
1
6752.16
1
6834.18
1
6754.61
1
6577.81
1
6617.88
1
6545.1
1
6651.72
1
6605.01
1
6613.81
1
6582.83
1
6555.44
1
6471.4
1
6528.33
1
6518.79
1
6415.22
1
6449.27
1
6355.24
1
6360.56
1
6358.56
1
6285.44
1
6210.83
1
6269.53
1
6182.48
1
5993.17
1
6080.66
1
6191.78
1
6056.53
1
6015.29
1
5923.91
1
6089.76
1
6019.26
1
6094.15
1
6102
1
6045.91
1
5824.42
1
5964.8
1
6050.56
1
5872.43
1
5972.07
1
5975.95
1
5859.78
1
5949.1
1
6003.99
1
5967.17
1
5982.2
1
6038.49
1
6088.95
1
6049.63
1
5945.5
1
5825.12
1
6038.17
1
5890.91
1
5897.4
1
5935.5
1
5943.84
1
6056.77
1
6104.39
1
6077.17
1
6090.55
1
6015.25
1
5961.36
1
6080.1
1
6030.86
1
6112.15
1
6085.06
1
6177.42
1
6132.68
1
6145.89
1
6256.61
1
6231.34
1
6168.14
1
6014.58
1
6117.04
1
6270.46
1
6258.23
1
6268.91
1
6320.99
1
6327.95
1
6446.02
1
6355.98
1
6474.99
1
6596.82
1
6716.1
1
6780.15
1
6902.82
1
6830.05
1
7044.43
1
7214.43
1
7278.35
1
7494.56
1
7722.35
1
8020.31
1
8259.02
1
8638.59
1
9019.08
1
9585.36
1
10549.8
1
11398.6
1
12387.8
1
13797
1
15148.9
1
16405.5
1
17296.7
1
17538.4
1
17435.2
1
17033.5
1
15767.2
1
14726.6
1
13322.8
1
12181.5
1
10908.6
1
9855.44
1
9072.78
1
8406.29
1
7784.13
1
7170.06
1
7054.78
1
6715.62
1
6468.24
1
6281.8
1
6181.79
1
6132.85
1
6044.84
1
6022.76
1
5973.79
1
5952.7
1
5845.56
1
5874.58
1
5823.9
1
5757.64
1
5700.45
1
5708.74
1
5695.42
1
5727.9
1
5657.7
1
5540.28
1
5596.96
1
5567.1
1
5529.56
1
5474.92
1
5531.18
1
5487.69
1
5547.48
1
5507.75
1
5519.07
1
5449.49
1
5418.15
1
5393.92
1
5460.8
1
5422.1
1
5531.94
1
5421.97
1
5480.36
1
5449.03
1
5572.37
1
5441.11
1
5368.66
1
5427.18
1
5448.15
1
5486.13
1
5547.65
1
5508.92
1
5539.11
1
5388.42
1
5501.47
1
5475.21
1
5460.32
1
5483.04
1
5489.35
1
5368.99
1
5481.71
1
5432.9
1
5391.73
1
5459.23
1
5464.43
1
5365.08
1
5477.83
1
5549.55
1
5523.25
1
5501.79
1
5373.88
1
5440.37
1
5453.56
1
5439.66
1
5419.09
1
5387.53
1
5412.99
1
5381.79
1
5405.79
1
5530.52
1
end of experiment