File: Vms/Experiment 2022-06-01_CuMnAs_14_Cu2p4.vms
VAMAS Surface Chemical Analysis Standard Data Transfer Format 1988 May 4
Specs
PHOIBOS HSA3500 DLD 150 R7[HWType 30:101] DLD
ppxcf1
?
1
Created by SpecsLab Prodigy, Version 4.91.3-r105809
NORM
REGULAR
1
0
0
0
0
0
1
Cu2p4
Transmission cyclic
2022
6
1
13
17
24
0
9
File = C:/Users/ppxcf1/Desktop/Data/XPS/01-Jun-2022/Experiment 2022-06-01_CuMnAs (1).sle
Group = Transmission cyclic
First of group = 1
Spectrum ID = 14
Analyzer lens = SmallArea:1.5kV
Analyzer slit = 4:7x20c\B:open
Scan mode = FixedAnalyzerTransmission
Kinetic energy start = 511.61
OrdinateRange = [-22.000000, 22.000000]
XPS
Al
1486.61
0
0
0
54.500000
180.000000
FAT
20
1
4.14
0
0
0
0
0
Cu2p4

-1
kinetic energy
eV
511.61
0.1
2
counts
d
Transmission
d
pulse counting
0.5
10
0
0
0
0
0
1002
7224
22411.2
1
1
10457.7
1
10417.3
1
10419.1
1
10448.5
1
10450
1
10526.9
1
10423.9
1
10521.7
1
10496.2
1
10323.5
1
10446.4
1
10321.4
1
10259.7
1
10320.3
1
10307.4
1
10590.4
1
10394.5
1
10273.7
1
10426.8
1
10251.8
1
10373.5
1
10479.9
1
10321.1
1
10398.7
1
10329.2
1
10406.5
1
10464.5
1
10462.6
1
10451.6
1
10536.6
1
10511
1
10464.7
1
10523.7
1
10404.9
1
10544
1
10350.5
1
10382.1
1
10482.3
1
10576.7
1
10727.5
1
10393.6
1
10367.8
1
10412.5
1
10491.4
1
10595.2
1
10491.3
1
10539.7
1
10303.8
1
10397.3
1
10498.6
1
10386.3
1
10479.3
1
10409.9
1
10377.5
1
10331.9
1
10330.3
1
10428.1
1
10512.9
1
10442.2
1
10418.6
1
10418.3
1
10583.1
1
10520.2
1
10483.5
1
10484.5
1
10504.4
1
10395
1
10512.9
1
10434.2
1
10316.1
1
10395
1
10337.7
1
10627.9
1
10335.1
1
10207.5
1
10428.5
1
10422.2
1
10369.9
1
10509.4
1
10479.7
1
10344.6
1
10305.1
1
10385.9
1
10324.2
1
10373.5
1
10375
1
10469
1
10340.7
1
10294.1
1
10221.7
1
10348.8
1
10476.1
1
10422.1
1
10076.5
1
10199.8
1
10307.7
1
10388.6
1
10358.4
1
10282.9
1
10458.9
1
10277.3
1
10208.4
1
10279.6
1
9997.65
1
10127.9
1
10114.9
1
10129.5
1
10016.1
1
9956.25
1
10249.3
1
10138.5
1
10183.4
1
10193.3
1
10020.3
1
10130.7
1
10305
1
10259.4
1
10080.3
1
9925.4
1
9897.07
1
9934.18
1
10078.1
1
9962.95
1
9958.77
1
9964.36
1
9982.72
1
9847.23
1
10017.8
1
9948.2
1
9950.36
1
9873.07
1
10028.8
1
10093.2
1
10130.5
1
10084.3
1
10038.4
1
9734.18
1
9977.17
1
9944.55
1
9936.49
1
9937.43
1
9966.86
1
9921.83
1
9913.39
1
9885.24
1
9870.2
1
9941.61
1
9977.43
1
9897.05
1
9882.05
1
10036.1
1
10154.7
1
10157
1
9959.46
1
9922.97
1
10142.5
1
10211
1
10120
1
9922.79
1
10145.9
1
10202.6
1
10050.7
1
10142.5
1
10140.1
1
10193.2
1
10222
1
10039.4
1
10085.6
1
10152.8
1
10044.1
1
9937.41
1
10246.3
1
10271.3
1
10205.6
1
10296.6
1
10375.3
1
10379.6
1
10349.4
1
10418.6
1
10384.9
1
10326.5
1
10269.4
1
10416.8
1
10534.2
1
10508
1
10349.2
1
10306.6
1
10543.7
1
10462.7
1
10655.9
1
10792.5
1
10610
1
10754.7
1
10810.9
1
10892.4
1
10941.6
1
11056.3
1
10963.9
1
10960.4
1
11296.2
1
11282.2
1
11386.6
1
11495.8
1
11714.3
1
11856.4
1
12002.1
1
12230.4
1
12655
1
12817.3
1
13308.5
1
13799.1
1
14143.7
1
14260.5
1
14689.2
1
15131
1
15273.5
1
15207.5
1
15224.2
1
15002
1
14675.5
1
14090.1
1
13865.6
1
13300
1
12883.9
1
12509.5
1
12145.7
1
11829.8
1
11495.9
1
11249.1
1
11114.8
1
10890.3
1
10870.8
1
10680.5
1
10582.3
1
10563.6
1
10538.1
1
10370
1
10489.6
1
10330.8
1
10206.5
1
10254.7
1
10431.5
1
10114.3
1
10165.8
1
10310.6
1
10208
1
10167.4
1
10117.6
1
10047.1
1
9999.68
1
10009.5
1
10138.9
1
10022.1
1
9889.34
1
9957.03
1
10013.5
1
9983.43
1
10091.7
1
9971
1
9989.01
1
10102.7
1
9962.07
1
10014.7
1
9939.67
1
9924.45
1
9831.95
1
9805.37
1
9668.85
1
9895.1
1
9836.55
1
9782.95
1
9607.08
1
9767.49
1
9856.12
1
9592.31
1
9591.15
1
9574.47
1
9613.23
1
9785.32
1
9734.76
1
9872.48
1
9673.75
1
9500.67
1
9610.54
1
9551.95
1
9608.08
1
9389.65
1
9335.68
1
9487.22
1
9515.56
1
9438.92
1
9373.91
1
9327.29
1
9401.37
1
9414.94
1
9413.98
1
9403.24
1
9449.61
1
9304.86
1
9225.66
1
9295.62
1
9372.51
1
9471.06
1
9272.46
1
9250.24
1
9007.55
1
9287.93
1
9212.04
1
9065.49
1
9148.62
1
9074.76
1
9031.99
1
9208.97
1
9103.68
1
9001.48
1
9091.34
1
8849.9
1
9014.6
1
8912.77
1
8943.24
1
8985.18
1
8788.94
1
8823.13
1
8803.7
1
8816.04
1
8758
1
8407.57
1
8385.14
1
8518.82
1
8613.84
1
8497.94
1
8499.13
1
8518.05
1
8423.69
1
8309.37
1
8256.53
1
8235.08
1
8122.11
1
8182.35
1
8296.32
1
8296.92
1
8074.92
1
8047.23
1
8057.21
1
8184.81
1
8133.24
1
8366.79
1
8292.19
1
8173.72
1
8233.46
1
8156.67
1
8107.67
1
8127.38
1
8110.91
1
8010.52
1
8112.83
1
8181.56
1
8186.25
1
8087.51
1
8058.98
1
8322.99
1
8114.06
1
8254.91
1
8235.29
1
8253
1
8117.26
1
8114.12
1
8306.71
1
8091.68
1
8046.02
1
8148.74
1
8208.6
1
8111.75
1
8142.58
1
8294.01
1
8302.25
1
8276.16
1
8421.98
1
8377.48
1
8220.23
1
8298.05
1
8310.63
1
8408.68
1
8523.03
1
8475.37
1
8664.84
1
8467.06
1
8603.35
1
8741.43
1
8756.76
1
8650.37
1
8716.95
1
9077.14
1
9115.98
1
9013.77
1
9266.83
1
9354.66
1
9454.75
1
9536.87
1
9828.69
1
10228
1
10550.8
1
10696.8
1
10935.8
1
11553.5
1
12202.4
1
12958.5
1
13929.4
1
15043.7
1
16396.3
1
17818.6
1
19562
1
20687.4
1
22192.9
1
22411.2
1
22158.1
1
21484.8
1
20349.1
1
18960.3
1
17301.2
1
15777.7
1
14118.6
1
12874.2
1
11713.9
1
10797.3
1
10053.4
1
9485.14
1
9084.78
1
8745.81
1
8494.62
1
8274.81
1
8210.28
1
8212.76
1
8098.35
1
7985.16
1
7906.1
1
7843.32
1
7771.15
1
7841.33
1
7859.24
1
7517.69
1
7602.96
1
7650.87
1
7917.96
1
7656.86
1
7368.65
1
7270.69
1
7656.44
1
7666.61
1
7637.67
1
7465.26
1
7483.46
1
7494.79
1
7233.26
1
7525.44
1
7615.96
1
7423.91
1
7272.74
1
7487.12
1
7571.76
1
7483.91
1
7432.2
1
7416.9
1
7290.8
1
7440.22
1
7446.23
1
7367.71
1
7299.01
1
7263.06
1
7332.45
1
7448.66
1
7239.12
1
7360.09
1
7370.81
1
7344.18
1
7329.33
1
7501.93
1
7442.27
1
7254.11
1
7382.86
1
7366.91
1
7250.19
1
7233.45
1
7281.96
1
7370.13
1
7402.73
1
7363.57
1
7371.82
1
7397.73
1
7412.49
1
7362.61
1
7332.2
1
7335.29
1
7349.85
1
7224
1
7430.99
1
7391.18
1
7320.79
1
7395
1
7291.58
1
7299.56
1
end of experiment