File: Vms/Experiment 2022-06-01_CuMnAs_10_VB3.vms
VAMAS Surface Chemical Analysis Standard Data Transfer Format 1988 May 4
Specs
PHOIBOS HSA3500 DLD 150 R7[HWType 30:101] DLD
ppxcf1
?
1
Created by SpecsLab Prodigy, Version 4.91.3-r105809
NORM
REGULAR
1
0
0
0
0
0
1
VB3
Transmission cyclic
2022
6
1
10
11
6
0
9
File = C:/Users/ppxcf1/Desktop/Data/XPS/01-Jun-2022/Experiment 2022-06-01_CuMnAs (1).sle
Group = Transmission cyclic
First of group = 1
Spectrum ID = 10
Analyzer lens = SmallArea:1.5kV
Analyzer slit = 4:7x20c\B:open
Scan mode = FixedAnalyzerTransmission
Kinetic energy start = 1456.61
OrdinateRange = [-22.000000, 22.000000]
XPS
Al
1486.61
0
0
0
54.500000
180.000000
FAT
20
1
4.14
0
0
0
0
0
VB3

-1
kinetic energy
eV
1456.61
0.1
2
counts
d
Transmission
d
pulse counting
0.1
10
0
0
0
0
0
622
1.38408
1373.61
1
1
179.317
1
164.972
1
168.437
1
162.558
1
173.191
1
186.274
1
190.792
1
155.586
1
148.916
1
164.454
1
152.508
1
163.447
1
180.392
1
173.71
1
164.326
1
178.31
1
170.989
1
146.115
1
149.962
1
152.157
1
167.7
1
161.251
1
152.069
1
169.992
1
160.982
1
164.607
1
170.602
1
182.309
1
177.732
1
166.659
1
188.415
1
169.436
1
163.339
1
159.847
1
157.63
1
169.199
1
174.487
1
168.641
1
186.046
1
169.969
1
173.251
1
150.961
1
177.389
1
182.566
1
182.215
1
160.141
1
176.196
1
201.894
1
169.26
1
153.665
1
136.857
1
158.244
1
185.039
1
189.247
1
175.104
1
159.507
1
163.32
1
148.332
1
175.44
1
180.714
1
170.107
1
163.358
1
190.544
1
189.604
1
170.939
1
157.97
1
157.656
1
181.477
1
177.06
1
162.072
1
170.202
1
156.941
1
176.839
1
180.316
1
150.174
1
171.043
1
165.092
1
173.942
1
177.006
1
160.342
1
161.986
1
179.573
1
159.003
1
181.977
1
180.556
1
176.645
1
224.613
1
228.459
1
219.285
1
245.89
1
232.692
1
267.275
1
294.121
1
352.518
1
413.105
1
535.96
1
644.947
1
838.238
1
1011.52
1
1123.48
1
1237.15
1
1317.77
1
1373.61
1
1367.66
1
1218.55
1
1107.57
1
900.312
1
691.168
1
534.25
1
405.14
1
316.926
1
246.741
1
222.566
1
201.224
1
179.195
1
170.371
1
152.255
1
159.379
1
147.863
1
160.016
1
154.311
1
149.249
1
139.38
1
126.261
1
126.361
1
136.074
1
119.744
1
131.012
1
128.412
1
123.853
1
114.815
1
112.386
1
102.408
1
128.962
1
103.115
1
115.215
1
107.173
1
101.413
1
106.194
1
120.832
1
125.585
1
112.798
1
129.705
1
100.139
1
113.269
1
113.79
1
97.9459
1
104.507
1
114.471
1
100.362
1
109.886
1
111.336
1
115.259
1
102.407
1
123.637
1
113.065
1
109.448
1
124.629
1
101.432
1
115.583
1
121.588
1
128.599
1
119.587
1
134.055
1
122.103
1
136.347
1
144.02
1
122.133
1
144.521
1
157.044
1
144.942
1
139.257
1
134.698
1
156.964
1
136.984
1
142.284
1
141.177
1
118.811
1
134.559
1
125.286
1
135.191
1
126.992
1
117.99
1
141.823
1
111.59
1
131.445
1
119.346
1
99.6272
1
127.996
1
99.2413
1
94.0544
1
103.627
1
121.293
1
106.357
1
100.357
1
88.8418
1
78.9245
1
88.568
1
101.119
1
91.5624
1
99.5085
1
92.2457
1
80.8975
1
79.7697
1
93.2857
1
103.963
1
75.2158
1
81.6027
1
67.8962
1
78.8225
1
89.7941
1
82.7395
1
91.2664
1
94.0513
1
94.5208
1
91.5589
1
105.093
1
108.692
1
114.101
1
120.843
1
118.235
1
137.02
1
143.931
1
140.54
1
152.675
1
141.455
1
153.357
1
160.114
1
157.452
1
151.393
1
157.22
1
196.606
1
165.508
1
184.422
1
182.136
1
183.4
1
192.341
1
198.521
1
213.878
1
237.68
1
259.722
1
284.892
1
270.046
1
288.462
1
308.585
1
384.723
1
390.829
1
428.055
1
483.756
1
516.374
1
508.737
1
567.773
1
573.38
1
623.725
1
612.733
1
669.684
1
632.347
1
646.13
1
600.861
1
546.266
1
573.558
1
532.794
1
504.471
1
464.974
1
365.626
1
351.397
1
330.391
1
299.043
1
332.097
1
280.794
1
265.382
1
256.619
1
241.3
1
238.185
1
216.229
1
229.586
1
222.563
1
197.98
1
180.118
1
185.902
1
174.604
1
159.538
1
150.358
1
127.289
1
138.739
1
140.021
1
122.476
1
113.128
1
98.0709
1
94.3143
1
84.135
1
69.106
1
73.5269
1
55.8782
1
45.7579
1
40.7226
1
34.0248
1
26.3708
1
18.0675
1
17.9184
1
18.4731
1
11.3404
1
7.21634
1
6.18057
1
3.2136
1
4.23463
1
1.38408
1
6.03666
1
5.28542
1
3.43462
1
5.96684
1
end of experiment